<!--left wrist_3_joint-->
    <joint name="left_wrist_3_link_to_left_wrist_2_link" type="revolute">
        <origin xyz="0.0 0.0 0.00" rpy="-1.5708 0.0 0.0"/>
        <parent link="left_wrist_2_link"/>
        <child link="left_wrist_3_link"/>
        <axis xyz="0.0 0.0 1"/>
        <limit lower="-6.28318530718" upper="6.28318530718" effort="12.0" velocity="6.28318530718"/>
    </joint>

    <!--3-->
    <link name="left_wrist_3_link">
        <inertial>
            <origin xyz="0.0 0.0 -0.0175" rpy="0.0 0.0 0.0"/>
            <mass value  ="0.35"/>
            <inertia ixx="0.000136267" ixy="0.0" ixz="0.0" iyy="0.000136267" iyz="0.0" izz="0.0004096"/>
        </inertial>
        <visual >
            <origin xyz="0.0 0.0 0.0" rpy="1.5708 0.0 0.0"/>
            <geometry>
                <mesh filename="meshes/wrist3.stl"/>
            </geometry>
            <material  name ="LightGrey"/>
        </visual>
        <collision>
            <origin xyz="0.0 0.0 0.0" rpy="1.5708 0.0 0.0"/>
            <geometry>
                <mesh filename="meshes/wrist3.stl"/>
            </geometry>
        </collision>
    </link>
